<?xml version="1.0"?>
<robot xmlns:xacro="http://ros.org/wiki/xacro">
  <xacro:macro name="motoman_epx1250" params="prefix">
    <!-- link list -->
    <link name="${prefix}base_link">
      <visual>
        <origin xyz="0 0 0" rpy="0 0 0"/>
        <geometry>
          <mesh filename="package://motoman_epx_support/meshes/epx1250/visual/base_link.stl"/>
        </geometry>
        <material name="blue">
          <color rgba="0 0 1 1"/>
        </material>
      </visual>
      <collision>
        <geometry>
          <mesh filename="package://motoman_epx_support/meshes/epx1250/collision/base_link.stl"/>
        </geometry>
        <material name="yellow">
          <color rgba="0 1 1 1"/>
        </material>
      </collision>
    </link>
    <link name="${prefix}link_s">
      <visual>
        <origin xyz="0 0 0" rpy="0 0 0"/>
        <geometry>
          <mesh filename="package://motoman_epx_support/meshes/epx1250/visual/link_s.stl"/>
        </geometry>
        <material name="blue"/>
      </visual>
      <collision>
        <origin xyz="0 0 0" rpy="0 0 0"/>
        <geometry>
          <mesh filename="package://motoman_epx_support/meshes/epx1250/collision/link_s.stl"/>
        </geometry>
        <material name="yellow"/>
      </collision>
    </link>
    <link name="${prefix}link_l">
      <visual>
        <origin xyz="0 0 0" rpy="0 0 0"/>
        <geometry>
          <mesh filename="package://motoman_epx_support/meshes/epx1250/visual/link_l.stl"/>
        </geometry>
        <material name="blue"/>
      </visual>
      <collision>
        <origin xyz="0 0 0" rpy="0 0 0"/>
        <geometry>
          <mesh filename="package://motoman_epx_support/meshes/epx1250/collision/link_l.stl"/>
        </geometry>
        <material name="yellow"/>
      </collision>
    </link>
    <link name="${prefix}link_u">
      <visual>
        <origin xyz="0 0 0" rpy="0 0 0"/>
        <geometry>
          <mesh filename="package://motoman_epx_support/meshes/epx1250/visual/link_u.stl"/>
        </geometry>
        <material name="blue"/>
      </visual>
      <collision>
        <origin xyz="0 0 0" rpy="0 0 0"/>
        <geometry>
          <mesh filename="package://motoman_epx_support/meshes/epx1250/collision/link_u.stl"/>
        </geometry>
        <material name="yellow"/>
      </collision>
    </link>
    <link name="${prefix}link_r">
      <visual>
        <origin xyz="0.520 0 0" rpy="0 0 0"/>
        <geometry>
          <mesh filename="package://motoman_epx_support/meshes/epx1250/visual/link_r.stl"/>
        </geometry>
        <material name="blue"/>
      </visual>
      <collision>
        <origin xyz="0.520 0 0" rpy="0 0 0"/>
        <geometry>
          <mesh filename="package://motoman_epx_support/meshes/epx1250/collision/link_r.stl"/>
        </geometry>
        <material name="yellow"/>
      </collision>
    </link>
    <link name="${prefix}link_b">
      <visual>
        <origin xyz="0 0 0" rpy="0 0 0"/>
        <geometry>
          <mesh filename="package://motoman_epx_support/meshes/epx1250/visual/link_b.stl"/>
        </geometry>
        <material name="blue"/>
      </visual>
      <collision>
        <origin xyz="0 0 0" rpy="0 0 0"/>
        <geometry>
          <mesh filename="package://motoman_epx_support/meshes/epx1250/collision/link_b.stl"/>
        </geometry>
        <material name="yellow"/>
      </collision>
    </link>
    <link name="${prefix}link_t">
      <visual>
        <origin xyz="0 0 0" rpy="0 0 0"/>
        <geometry>
          <mesh filename="package://motoman_epx_support/meshes/epx1250/visual/link_t.stl"/>
        </geometry>
        <material name="black">
          <color rgba = "1 1 1 1"/>
        </material>
      </visual>
      <collision>
        <origin xyz="0 0 0" rpy="0 0 0"/>
        <geometry>
          <mesh filename="package://motoman_epx_support/meshes/epx1250/collision/link_t.stl"/>
        </geometry>
        <material name="black"/>
      </collision>
    </link>
    <link name="${prefix}tool0"/>
    <!-- end of link list -->
    <!-- joint list -->
    <joint name="${prefix}joint_s" type="revolute">
      <origin xyz="0 0 0.310" rpy="0 0 0"/>
      <parent link="${prefix}base_link"/>
      <child link="${prefix}link_s"/>
      <axis xyz="0 0 1"/>
      <limit lower="${radians(-170)}" upper="${radians(170)}" effort="0" velocity="${radians(185)}"/>
    </joint>
    <joint name="${prefix}joint_l" type="revolute">
      <origin xyz="0.200 0 0" rpy="0 0 0"/>
      <parent link="${prefix}link_s"/>
      <child link="${prefix}link_l"/>
      <axis xyz="0 1 0"/>
      <limit lower="${radians(-65)}" upper="${radians(120)}" effort="0" velocity="${radians(185)}"/>
    </joint>
    <joint name="${prefix}joint_u" type="revolute">
      <origin xyz="0 0 0.520" rpy="0 0 0"/>
      <parent link="${prefix}link_l"/>
      <child link="${prefix}link_u"/>
      <axis xyz="0 1 0"/>
      <limit lower="${radians(-165)}" upper="${radians(205)}" effort="0" velocity="${radians(185)}"/>
    </joint>
    <joint name="${prefix}joint_r" type="revolute">
      <origin xyz="0 0 0.130" rpy="0 0 0"/>
      <parent link="${prefix}link_u"/>
      <child link="${prefix}link_r"/>
      <axis xyz="1 0 0"/>
      <limit lower="${radians(-190)}" upper="${radians(190)}" effort="0" velocity="${radians(360)}"/>
    </joint>
    <joint name="${prefix}joint_b" type="revolute">
      <origin xyz="0.520 0 0" rpy="0 0 0"/>
      <parent link="${prefix}link_r"/>
      <child link="${prefix}link_b"/>
      <axis xyz="0 1 0"/>
      <limit lower="${radians(-145)}" upper="${radians(145)}" effort="0" velocity="${radians(410)}"/>
    </joint>
    <joint name="${prefix}joint_t" type="revolute">
      <origin xyz="0.0865 0 0" rpy="0 0 0"/>
      <parent link="${prefix}link_b"/>
      <child link="${prefix}link_t"/>
      <axis xyz="1 0 0"/>
      <limit lower="${radians(-360)}" upper="${radians(360)}" effort="0" velocity="${radians(500)}"/>
    </joint>
    <joint name="${prefix}joint_t-tool0" type="fixed">
      <origin xyz="0 0 0" rpy="0 ${radians(90)} 0"/>
      <parent link="${prefix}link_t"/>
      <child link="${prefix}tool0"/>
    </joint>
    <!-- end of joint list -->
    <!-- ROS base_link to Robot Manufacturer World Coordinates transform -->
    <link name="${prefix}base"/>
    <joint name="${prefix}base_link-base" type="fixed">
      <origin xyz="0 0 0.310" rpy="0 0 0"/>
      <parent link="${prefix}base_link"/>
      <child link="${prefix}base"/>
    </joint>
  </xacro:macro>
</robot>
