<?xml version="1.0" ?>
<robot xmlns:xacro="http://ros.org/wiki/xacro">
  <xacro:macro name="bmda3" params="prefix">
  <!-- link list   -->
	  <link name="${prefix}base_link">
		  <origin xyz="0 0 0" rpy="0 0 0"/>
  	</link>

    <link name="${prefix}base">
      <visual>
      <origin
        xyz="0 0 0"
        rpy="0 0 0" />
      <geometry>
        <mesh
          filename="package://motoman_bmda3_support/meshes/bmda3/visual/base.stl" />
      </geometry>
      <material
        name="">
        <color
          rgba="0.75294 0.75294 0.75294 1" />
      </material>
    </visual>
    <collision>
      <origin
        xyz="0 0 0"
        rpy="0 0 0" />
      <geometry>
        <mesh
          filename="package://motoman_bmda3_support/meshes/bmda3/collision/base.stl" />
      </geometry>
    </collision>
  </link>

  <link
    name="${prefix}waist_link">
    <visual>
      <origin
        xyz="0 0 0"
        rpy="0 0 0" />
      <geometry>
        <mesh
          filename="package://motoman_bmda3_support/meshes/bmda3/visual/waist_link.stl" />
      </geometry>
      <material
        name="">
        <color
          rgba="0.75294 0.75294 0.75294 1" />
      </material>
    </visual>
    <collision>
      <origin
        xyz="0 0 0"
        rpy="0 0 0" />
      <geometry>
        <mesh
          filename="package://motoman_bmda3_support/meshes/bmda3/collision/waist_link.stl" />
      </geometry>
    </collision>
  </link>
  
  <link
    name="${prefix}right_link_l">
    <visual>
      <origin
        xyz="0 0 0"
        rpy="0 0 0" />
      <geometry>
        <mesh
          filename="package://motoman_bmda3_support/meshes/bmda3/visual/right_link_l.stl" />
      </geometry>
      <material
        name="">
        <color
          rgba="0.75294 0.75294 0.75294 1" />
      </material>
    </visual>
    <collision>
      <origin
        xyz="0 0 0"
        rpy="0 0 0" />
      <geometry>
        <mesh
          filename="package://motoman_bmda3_support/meshes/bmda3/collision/right_link_l.stl" />
      </geometry>
    </collision>
  </link>
  
  <link
    name="${prefix}right_link_e">
    <visual>
      <origin
        xyz="0 0 0"
        rpy="0 0 0" />
      <geometry>
        <mesh
          filename="package://motoman_bmda3_support/meshes/bmda3/visual/right_link_e.stl" />
      </geometry>
      <material
        name="">
        <color
          rgba="0.75294 0.75294 0.75294 1" />
      </material>
    </visual>
    <collision>
      <origin
        xyz="0 0 0"
        rpy="0 0 0" />
      <geometry>
        <mesh
          filename="package://motoman_bmda3_support/meshes/bmda3/collision/right_link_e.stl" />
      </geometry>
    </collision>
  </link>
 
  <link
    name="${prefix}right_link_u">
     <visual>
      <origin
        xyz="0 0 0"
        rpy="0 0 0" />
      <geometry>
        <mesh
          filename="package://motoman_bmda3_support/meshes/bmda3/visual/right_link_u.stl" />
      </geometry>
      <material
        name="">
        <color
          rgba="0.752941176470588 0.752941176470588 0.752941176470588 1" />
      </material>
    </visual>
    <collision>
      <origin
        xyz="0 0 0"
        rpy="0 0 0" />
      <geometry>
        <mesh
          filename="package://motoman_bmda3_support/meshes/bmda3/collision/right_link_u.stl" />
      </geometry>
    </collision>
  </link>
  
  <link
    name="${prefix}right_link_r">
    <visual>
      <origin
        xyz="0 0 0"
        rpy="0 0 0" />
      <geometry>
        <mesh
          filename="package://motoman_bmda3_support/meshes/bmda3/visual/right_link_r.stl" />
      </geometry>
      <material
        name="">
        <color
          rgba="0.752941176470588 0.752941176470588 0.752941176470588 1" />
      </material>
    </visual>
    <collision>
      <origin
        xyz="0 0 0"
        rpy="0 0 0" />
      <geometry>
        <mesh
          filename="package://motoman_bmda3_support/meshes/bmda3/collision/right_link_r.stl" />
      </geometry>
    </collision>
  </link>
  
  <link
    name="${prefix}right_link_b">
    <visual>
      <origin
        xyz="0 0 0"
        rpy="0 0 0" />
      <geometry>
        <mesh
          filename="package://motoman_bmda3_support/meshes/bmda3/visual/right_link_b.stl" />
      </geometry>
      <material
        name="">
        <color
          rgba="0.752941176470588 0.752941176470588 0.752941176470588 1" />
      </material>
    </visual>
    <collision>
      <origin
        xyz="0 0 0"
        rpy="0 0 0" />
      <geometry>
        <mesh
          filename="package://motoman_bmda3_support/meshes/bmda3/collision/right_link_b.stl" />
      </geometry>
    </collision>
  </link>
  
  <link
    name="${prefix}right_link_t">
    <visual>
      <origin
        xyz="0 0 0"
        rpy="0 0 0" />
      <geometry>
        <mesh
          filename="package://motoman_bmda3_support/meshes/bmda3/visual/right_link_t.stl" />
      </geometry>
      <material
        name="">
        <color
          rgba="0.752941176470588 0.752941176470588 0.752941176470588 1" />
      </material>
    </visual>
    <collision>
      <origin
        xyz="0 0 0"
        rpy="0 0 0" />
      <geometry>
        <mesh
          filename="package://motoman_bmda3_support/meshes/bmda3/collision/right_link_t.stl" />
      </geometry>
    </collision>
  </link>

  <link name="${prefix}right_tool0" />
  
  <link
    name="${prefix}left_link_l">
    <visual>
      <origin
        xyz="0 0 0"
        rpy="0 0 0" />
      <geometry>
        <mesh
          filename="package://motoman_bmda3_support/meshes/bmda3/visual/left_link_l.stl" />
      </geometry>
      <material
        name="">
        <color
          rgba="0.752941176470588 0.752941176470588 0.752941176470588 1" />
      </material>
    </visual>
    <collision>
      <origin
        xyz="0 0 0"
        rpy="0 0 0" />
      <geometry>
        <mesh
          filename="package://motoman_bmda3_support/meshes/bmda3/collision/left_link_l.stl" />
      </geometry>
    </collision>
  </link>
  
  <link
    name="${prefix}left_link_e">
    <visual>
      <origin
        xyz="0 0 0"
        rpy="0 0 0" />
      <geometry>
        <mesh
          filename="package://motoman_bmda3_support/meshes/bmda3/visual/left_link_e.stl" />
      </geometry>
      <material
        name="">
        <color
          rgba="0.752941176470588 0.752941176470588 0.752941176470588 1" />
      </material>
    </visual>
    <collision>
      <origin
        xyz="0 0 0"
        rpy="0 0 0" />
      <geometry>
        <mesh
          filename="package://motoman_bmda3_support/meshes/bmda3/collision/left_link_e.stl" />
      </geometry>
    </collision>
  </link>
  
  <link
    name="${prefix}left_link_u">
    <visual>
      <origin
        xyz="0 0 0"
        rpy="0 0 0" />
      <geometry>
        <mesh
          filename="package://motoman_bmda3_support/meshes/bmda3/visual/left_link_u.stl" />
      </geometry>
      <material
        name="">
        <color
          rgba="0.752941176470588 0.752941176470588 0.752941176470588 1" />
      </material>
    </visual>
    <collision>
      <origin
        xyz="0 0 0"
        rpy="0 0 0" />
      <geometry>
        <mesh
          filename="package://motoman_bmda3_support/meshes/bmda3/collision/left_link_u.stl" />
      </geometry>
    </collision>
  </link>
  
  <link
    name="${prefix}left_link_r">
    <visual>
      <origin
        xyz="0 0 0"
        rpy="0 0 0" />
      <geometry>
        <mesh
          filename="package://motoman_bmda3_support/meshes/bmda3/visual/left_link_r.stl" />
      </geometry>
      <material
        name="">
        <color
          rgba="0.752941176470588 0.752941176470588 0.752941176470588 1" />
      </material>
    </visual>
    <collision>
      <origin
        xyz="0 0 0"
        rpy="0 0 0" />
      <geometry>
        <mesh
          filename="package://motoman_bmda3_support/meshes/bmda3/collision/left_link_r.stl" />
      </geometry>
    </collision>
  </link>
  
  <link
    name="${prefix}left_link_b">
    <visual>
      <origin
        xyz="0 0 0"
        rpy="0 0 0" />
      <geometry>
        <mesh
          filename="package://motoman_bmda3_support/meshes/bmda3/visual/left_link_b.stl" />
      </geometry>
      <material
        name="">
        <color
          rgba="0.752941176470588 0.752941176470588 0.752941176470588 1" />
      </material>
    </visual>
    <collision>
      <origin
        xyz="0 0 0"
        rpy="0 0 0" />
      <geometry>
        <mesh
          filename="package://motoman_bmda3_support/meshes/bmda3/collision/left_link_b.stl" />
      </geometry>
    </collision>
  </link>

  <link
    name="${prefix}left_link_t">
    <visual>
      <origin
        xyz="0 0 0"
        rpy="0 0 0" />
      <geometry>
        <mesh
          filename="package://motoman_bmda3_support/meshes/bmda3/visual/left_link_t.stl" />
      </geometry>
      <material
        name="">
        <color
          rgba="0.752941176470588 0.752941176470588 0.752941176470588 1" />
      </material>
    </visual>
    <collision>
      <origin
        xyz="0 0 0"
        rpy="0 0 0" />
      <geometry>
        <mesh
          filename="package://motoman_bmda3_support/meshes/bmda3/collision/left_link_t.stl" />
      </geometry>
    </collision>
  </link>
  
  <link name="${prefix}left_tool0"/>


    <!--end of link list -->
    <!-- joint list -->  
    <joint name="${prefix}base_link-base" type="fixed">
   	<origin xyz="0 0 0" rpy="0 0 0"/>
   	<parent link="${prefix}base_link" />
   	<child link="${prefix}base"/>
  	</joint>
    <joint name="${prefix}waist" type="revolute"> 
          <parent link="${prefix}base" />
          <child  link="${prefix}waist_link" />
          <origin xyz="0 0 0.3305" rpy="0 0 0" />
          <axis xyz="0 0 1" />
          <limit lower="-3.1415" upper="3.1415" effort="0" velocity="2.27" />
    </joint>
    <joint name="${prefix}right_joint_s" type="revolute">
          <parent link="${prefix}waist_link" />
          <child link="${prefix}right_link_l" />
          <origin xyz="0.15002 -0.099 0.12951" rpy="0 0 0" />
          <axis xyz="0 1 0" />
          <limit lower="-1.570" upper="3.1415" effort="0" velocity="2.97" />
    </joint>
    <joint name="${prefix}right_joint_l" type="revolute">    
          <parent link="${prefix}right_link_l" />
          <child link="${prefix}right_link_e" />
          <origin xyz="0 -0.151 0" rpy="0 0 0" />    
          <axis xyz="0 0 1" />
          <limit lower="-1.745" upper="1.745" effort="0" velocity="2.62" />
    </joint>
    <joint name="${prefix}right_joint_e" type="revolute">
          <parent link="${prefix}right_link_e" />
          <child link="${prefix}right_link_u" />
          <origin xyz="0 -0.23549999999989 0" rpy="0 0 0" />          
          <axis xyz="0 1 0" />
          <limit lower="-2.966" upper="2.966" effort="0" velocity="2.97" />
    </joint>
    <joint name="${prefix}right_joint_u" type="revolute">
          <parent link="${prefix}right_link_u" />
          <child link="${prefix}right_link_r" />
          <origin xyz="0.065002 -0.1445 0" rpy="0 0 0" />          
          <axis xyz="0 0 -1" />
          <limit lower="-1.396" upper="0.7504" effort="0" velocity="2.97" />
    </joint>
    <joint name="${prefix}right_joint_r" type="revolute">
          <parent link="${prefix}right_link_r" />
          <child link="${prefix}right_link_b" />
          <origin xyz="0.35997 -0.05 0" rpy="0 0 0" />          
          <axis xyz="1 0 0" />
          <limit lower="-3.1415" upper="3.1415" effort="0" velocity="3.49" />
    </joint>
    <joint name="${prefix}right_joint_b" type="revolute">
          <parent link="${prefix}right_link_b" />
          <child link="${prefix}right_link_t" />
          <origin xyz="0 0 0" rpy="0 0 0" />
          <axis xyz="0 0 -1" />
          <limit lower="-1.9198" upper="1.9198" effort="0" velocity="3.49" />
    </joint>
    <joint name="${prefix}right_joint_t" type="revolute">
          <parent link="${prefix}right_link_t" />
          <child link="${prefix}right_tool0" />
          <origin xyz="0.138 0 0" rpy="0 0 0"  />
          <axis xyz="1 0 0" />
          <limit lower="-4.712" upper="4.712" effort="0" velocity="6.11" />
    </joint>
    
    <joint name="${prefix}left_joint_s" type="revolute">
          <parent link="${prefix}waist_link" />
          <child link="${prefix}left_link_l" />
          <origin xyz="0.15003 0.099 0.1295" rpy="0 0 0" />
          <axis xyz="0 1 0" />
          <limit lower="-1.570" upper="3.1415" effort="0" velocity="2.97" />
    </joint>
    <joint name="${prefix}left_joint_l" type="revolute">
          <parent link="${prefix}left_link_l" />
          <child link="${prefix}left_link_e" />
          <origin xyz="0 0.151 0" rpy="0 0 0" />
          <axis xyz="0 0 -1" />
          <limit lower="-1.745" upper="1.745" effort="0" velocity="2.62" />
    </joint>
    <joint name="${prefix}left_joint_e" type="revolute">
          <parent link="${prefix}left_link_e" />
          <child link="${prefix}left_link_u" />
          <origin xyz="0 0.23549999999989 0" rpy="0 0 0" />
          <axis xyz="0 1 0" />
        <limit lower="-2.966" upper="2.966" effort="0" velocity="2.97" />
    </joint>
    <joint name="${prefix}left_joint_u" type="revolute">
          <parent link="${prefix}left_link_u" />
          <child link="${prefix}left_link_r" />
          <origin xyz="0.065 0.1445 0" rpy="0 0 0" />
          <axis xyz="0 0 1" />
          <limit lower="-1.396" upper="0.7504" effort="0" velocity="2.97" />
    </joint>
    <joint name="${prefix}left_joint_r" type="revolute">
          <parent link="${prefix}left_link_r" />
          <child link="${prefix}left_link_b" />
          <origin xyz="0.35997 0.05 0" rpy="0 0 0" />
          <axis xyz="-1 0 0" />
          <limit lower="-3.1415" upper="3.1415" effort="0" velocity="3.49" />
    </joint>
    <joint name="${prefix}left_joint_b" type="revolute">
          <parent link="${prefix}left_link_b" />
          <child link="${prefix}left_link_t" />
          <origin xyz="0 0 0" rpy="0 0 0" />
          <axis xyz="0 0 1" />
          <limit lower="-1.9198" upper="1.9198" effort="0" velocity="3.49" />
    </joint>
     <joint name="${prefix}left_joint_t" type="revolute">
          <parent link="${prefix}left_link_t" />
          <child link="${prefix}left_tool0" />
          <origin xyz="0.138 0 0" rpy="0 0 0" />
          <axis xyz="-1 0 0" />
          <limit lower="-4.712" upper="4.712" effort="0" velocity="6.11" />
    </joint>
 

		<!-- end of joint list -->
	</xacro:macro>
</robot>
