<?xml version="1.0" ?>
<robot xmlns:xacro="http://ros.org/wiki/xacro">
    <xacro:macro name="motoman_bmda3" params="prefix">
		<!-- link list -->
		<link name="world">
    		<origin xyz="0 0 0" rpy="0 0 0"/>
  	</link>
		<link name="${prefix}base_link">
      <visual>
      <origin
        xyz="0 0 0"
        rpy="0 0 0" />
      <geometry>
        <mesh
          filename="package://motoman_bmda3_support/meshes/bmda3/visual/base_link.stl" />
      </geometry>
      <material
        name="">
        <color
          rgba="0.75294 0.75294 0.75294 1" />
      </material>
    </visual>
    <collision>
      <origin
        xyz="0 0 0"
        rpy="0 0 0" />
      <geometry>
        <mesh
          filename="package://motoman_bmda3_support/meshes/bmda3/collision/base_link.stl" />
      </geometry>
    </collision>
  </link>
  <link
    name="${prefix}waist_link">
    <visual>
      <origin
        xyz="0 0 0"
        rpy="0 0 0" />
      <geometry>
        <mesh
          filename="package://motoman_bmda3_support/meshes/bmda3/visual/waist_link.stl" />
      </geometry>
      <material
        name="">
        <color
          rgba="0.75294 0.75294 0.75294 1" />
      </material>
    </visual>
    <collision>
      <origin
        xyz="0 0 0"
        rpy="0 0 0" />
      <geometry>
        <mesh
          filename="package://motoman_bmda3_support/meshes/bmda3/collision/waist_link.stl" />
      </geometry>
    </collision>
  </link>
  
  <link
    name="${prefix}right_L_link">
    <visual>
      <origin
        xyz="0 0 0"
        rpy="0 0 0" />
      <geometry>
        <mesh
          filename="package://motoman_bmda3_support/meshes/bmda3/visual/right_L_link.stl" />
      </geometry>
      <material
        name="">
        <color
          rgba="0.75294 0.75294 0.75294 1" />
      </material>
    </visual>
    <collision>
      <origin
        xyz="0 0 0"
        rpy="0 0 0" />
      <geometry>
        <mesh
          filename="package://motoman_bmda3_support/meshes/bmda3/collision/right_L_link.stl" />
      </geometry>
    </collision>
  </link>
  
  <link
    name="${prefix}right_E_link">
    <visual>
      <origin
        xyz="0 0 0"
        rpy="0 0 0" />
      <geometry>
        <mesh
          filename="package://motoman_bmda3_support/meshes/bmda3/visual/right_E_link.stl" />
      </geometry>
      <material
        name="">
        <color
          rgba="0.75294 0.75294 0.75294 1" />
      </material>
    </visual>
    <collision>
      <origin
        xyz="0 0 0"
        rpy="0 0 0" />
      <geometry>
        <mesh
          filename="package://motoman_bmda3_support/meshes/bmda3/collision/right_E_link.stl" />
      </geometry>
    </collision>
  </link>
 
  <link
    name="${prefix}right_U_link">
     <visual>
      <origin
        xyz="0 0 0"
        rpy="0 0 0" />
      <geometry>
        <mesh
          filename="package://motoman_bmda3_support/meshes/bmda3/visual/right_U_link.stl" />
      </geometry>
      <material
        name="">
        <color
          rgba="0.752941176470588 0.752941176470588 0.752941176470588 1" />
      </material>
    </visual>
    <collision>
      <origin
        xyz="0 0 0"
        rpy="0 0 0" />
      <geometry>
        <mesh
          filename="package://motoman_bmda3_support/meshes/bmda3/collision/right_U_link.stl" />
      </geometry>
    </collision>
  </link>
  
  <link
    name="${prefix}right_R_link">
    <visual>
      <origin
        xyz="0 0 0"
        rpy="0 0 0" />
      <geometry>
        <mesh
          filename="package://motoman_bmda3_support/meshes/bmda3/visual/right_R_link.stl" />
      </geometry>
      <material
        name="">
        <color
          rgba="0.752941176470588 0.752941176470588 0.752941176470588 1" />
      </material>
    </visual>
    <collision>
      <origin
        xyz="0 0 0"
        rpy="0 0 0" />
      <geometry>
        <mesh
          filename="package://motoman_bmda3_support/meshes/bmda3/collision/right_R_link.stl" />
      </geometry>
    </collision>
  </link>
  
  <link
    name="${prefix}right_B_link">
    <visual>
      <origin
        xyz="0 0 0"
        rpy="0 0 0" />
      <geometry>
        <mesh
          filename="package://motoman_bmda3_support/meshes/bmda3/visual/right_B_link.stl" />
      </geometry>
      <material
        name="">
        <color
          rgba="0.752941176470588 0.752941176470588 0.752941176470588 1" />
      </material>
    </visual>
    <collision>
      <origin
        xyz="0 0 0"
        rpy="0 0 0" />
      <geometry>
        <mesh
          filename="package://motoman_bmda3_support/meshes/bmda3/collision/right_B_link.stl" />
      </geometry>
    </collision>
  </link>
  
  <link
    name="${prefix}right_T_link">
    <visual>
      <origin
        xyz="0 0 0"
        rpy="0 0 0" />
      <geometry>
        <mesh
          filename="package://motoman_bmda3_support/meshes/bmda3/visual/right_T_link.stl" />
      </geometry>
      <material
        name="">
        <color
          rgba="0.752941176470588 0.752941176470588 0.752941176470588 1" />
      </material>
    </visual>
    <collision>
      <origin
        xyz="0 0 0"
        rpy="0 0 0" />
      <geometry>
        <mesh
          filename="package://motoman_bmda3_support/meshes/bmda3/collision/right_T_link.stl" />
      </geometry>
    </collision>
  </link>
  
  <link
    name="${prefix}right_tool_0">
    <visual>
      <origin
        xyz="0 0 0"
        rpy="0 0 0" />
      <geometry>
        <mesh
          filename="package://motoman_bmda3_support/meshes/bmda3/visual/right_tool_0.stl" />
      </geometry>
      <material
        name="">
        <color
          rgba="0.752941176470588 0.752941176470588 0.752941176470588 1" />
      </material>
    </visual>
    <collision>
      <origin
        xyz="0 0 0"
        rpy="0 0 0" />
      <geometry>
        <mesh
          filename="package://motoman_bmda3_support/meshes/bmda3/collision/right_tool_0.stl" />
      </geometry>
    </collision>
  </link>
  
  <link
    name="${prefix}left_L_link">
    <visual>
      <origin
        xyz="0 0 0"
        rpy="0 0 0" />
      <geometry>
        <mesh
          filename="package://motoman_bmda3_support/meshes/bmda3/visual/left_L_link.stl" />
      </geometry>
      <material
        name="">
        <color
          rgba="0.752941176470588 0.752941176470588 0.752941176470588 1" />
      </material>
    </visual>
    <collision>
      <origin
        xyz="0 0 0"
        rpy="0 0 0" />
      <geometry>
        <mesh
          filename="package://motoman_bmda3_support/meshes/bmda3/collision/left_L_link.stl" />
      </geometry>
    </collision>
  </link>
  
  <link
    name="${prefix}left_E_link">
    <visual>
      <origin
        xyz="0 0 0"
        rpy="0 0 0" />
      <geometry>
        <mesh
          filename="package://motoman_bmda3_support/meshes/bmda3/visual/left_E_link.stl" />
      </geometry>
      <material
        name="">
        <color
          rgba="0.752941176470588 0.752941176470588 0.752941176470588 1" />
      </material>
    </visual>
    <collision>
      <origin
        xyz="0 0 0"
        rpy="0 0 0" />
      <geometry>
        <mesh
          filename="package://motoman_bmda3_support/meshes/bmda3/collision/left_E_link.stl" />
      </geometry>
    </collision>
  </link>
  
  <link
    name="${prefix}left_U_link">
    <visual>
      <origin
        xyz="0 0 0"
        rpy="0 0 0" />
      <geometry>
        <mesh
          filename="package://motoman_bmda3_support/meshes/bmda3/visual/left_U_link.stl" />
      </geometry>
      <material
        name="">
        <color
          rgba="0.752941176470588 0.752941176470588 0.752941176470588 1" />
      </material>
    </visual>
    <collision>
      <origin
        xyz="0 0 0"
        rpy="0 0 0" />
      <geometry>
        <mesh
          filename="package://motoman_bmda3_support/meshes/bmda3/collision/left_U_link.stl" />
      </geometry>
    </collision>
  </link>
  
  <link
    name="${prefix}left_R_link">
    <visual>
      <origin
        xyz="0 0 0"
        rpy="0 0 0" />
      <geometry>
        <mesh
          filename="package://motoman_bmda3_support/meshes/bmda3/visual/left_R_link.stl" />
      </geometry>
      <material
        name="">
        <color
          rgba="0.752941176470588 0.752941176470588 0.752941176470588 1" />
      </material>
    </visual>
    <collision>
      <origin
        xyz="0 0 0"
        rpy="0 0 0" />
      <geometry>
        <mesh
          filename="package://motoman_bmda3_support/meshes/bmda3/collision/left_R_link.stl" />
      </geometry>
    </collision>
  </link>
  
  <link
    name="${prefix}left_B_link">
    <visual>
      <origin
        xyz="0 0 0"
        rpy="0 0 0" />
      <geometry>
        <mesh
          filename="package://motoman_bmda3_support/meshes/bmda3/visual/left_B_link.stl" />
      </geometry>
      <material
        name="">
        <color
          rgba="0.752941176470588 0.752941176470588 0.752941176470588 1" />
      </material>
    </visual>
    <collision>
      <origin
        xyz="0 0 0"
        rpy="0 0 0" />
      <geometry>
        <mesh
          filename="package://motoman_bmda3_support/meshes/bmda3/collision/left_B_link.stl" />
      </geometry>
    </collision>
  </link>
    <link
    name="${prefix}left_T_link">
    <visual>
      <origin
        xyz="0 0 0"
        rpy="0 0 0" />
      <geometry>
        <mesh
          filename="package://motoman_bmda3_support/meshes/bmda3/visual/left_T_link.stl" />
      </geometry>
      <material
        name="">
        <color
          rgba="0.752941176470588 0.752941176470588 0.752941176470588 1" />
      </material>
    </visual>
    <collision>
      <origin
        xyz="0 0 0"
        rpy="0 0 0" />
      <geometry>
        <mesh
          filename="package://motoman_bmda3_support/meshes/bmda3/collision/left_T_link.stl" />
      </geometry>
    </collision>
  </link>
 
  <link
    name="${prefix}left_tool_0">
    <visual>
      <origin
        xyz="0 0 0"
        rpy="0 0 0" />
      <geometry>
        <mesh
          filename="package://motoman_bmda3_support/meshes/bmda3/visual/left_tool_0.stl" />
      </geometry>
      <material
        name="">
        <color
          rgba="0.752941176470588 0.752941176470588 0.752941176470588 1" />
      </material>
    </visual>
    <collision>
      <origin
        xyz="0 0 0"
        rpy="0 0 0" />
      <geometry>
        <mesh
          filename="package://motoman_bmda3_support/meshes/bmda3/collision/left_tool_0.stl" />
      </geometry>
    </collision>
  </link>
    <!--end of link list -->
    <!-- joint list -->
    <joint name="world-base" type="fixed">
   	  	 	<origin xyz="0 0 0" rpy="0 0 0"/>
   	  	 	<parent link="world" />
   	  	 	<child link="base_link"/>
  	</joint>
    <joint name="${prefix}waist_axis" type="revolute"> 
          <parent link="base_link" />
          <child  link="waist_link" />
          <origin xyz="0 0 0.3305" rpy="0 0 0" />
          <axis xyz="0 0 1" />
          <limit lower="-3.14" upper="3.14" effort="0" velocity="2.27" />
    </joint>
    <joint name="${prefix}right_S_axis" type="revolute">
          <parent link="waist_link" />
          <child link="right_L_link" />
          <origin xyz="0.15002 -0.099 0.12951" rpy="0 0 0" />
          <axis xyz="0 1 0" />
          <limit lower="-1.57" upper="3.14" effort="0" velocity="2.97" />
    </joint>
    <joint name="${prefix}right_L_axis" type="revolute">    
          <parent link="right_L_link" />
          <child link="right_E_link" />
          <origin xyz="0 -0.151 0" rpy="0 0 0" />    
          <axis xyz="0 0 1" />
          <limit lower="-1.745" upper="1.745" effort="0" velocity="2.62" />
    </joint>
    <joint name="${prefix}right_E_axis" type="revolute">
          <parent link="right_E_link" />
          <child link="right_U_link" />
          <origin xyz="0 -0.23549999999989 0" rpy="0 0 0" />          
          <axis xyz="0 1 0" />
          <limit lower="-2.966" upper="2.966" effort="0" velocity="2.97" />
    </joint>
    <joint name="${prefix}right_U_axis" type="revolute">
          <parent link="right_U_link" />
          <child link="right_R_link" />
          <origin xyz="0.065002 -0.1445 0" rpy="0 0 0" />          
          <axis xyz="0 0 -1" />
          <limit lower="-1.396" upper="0.7504" effort="0" velocity="2.97" />
    </joint>
    <joint name="${prefix}right_R_axis" type="revolute">
          <parent link="right_R_link" />
          <child link="right_B_link" />
          <origin xyz="0.35997 -0.05 0" rpy="0 0 0" />          
          <axis xyz="1 0 0" />
          <limit lower="-3.1415" upper="3.1415" effort="0" velocity="3.49" />
    </joint>
    <joint name="${prefix}right_B_axis" type="revolute">
          <parent link="right_B_link" />
          <child link="right_T_link" />
          <origin xyz="0 0 0" rpy="0 0 0" />
          <axis xyz="0 0 -1" />
          <limit lower="-1.9198" upper="1.9198" effort="0" velocity="3.49" />
    </joint>
    <joint name="${prefix}right_T_axis" type="revolute">
          <parent link="right_T_link" />
          <child link="right_tool_0" />
          <origin xyz="0.138 0 0" rpy="0 0 0"  />
          <axis xyz="1 0 0" />
          <limit lower="-4.712" upper="4.712" effort="0" velocity="6.11" />
    </joint>
    <joint name="${prefix}left_S_axis" type="revolute">
          <parent link="waist_link" />
          <child link="left_L_link" />
          <origin xyz="0.15003 0.099 0.1295" rpy="0 0 0" />
          <axis xyz="0 1 0" />
          <limit lower="-1.57" upper="3.1415" effort="0" velocity="2.97" />
    </joint>
    <joint name="${prefix}left_L_axis" type="revolute">
          <parent link="left_L_link" />
          <child link="left_E_link" />
          <origin xyz="0 0.151 0" rpy="0 0 0" />
          <axis xyz="0 0 -1" />
          <limit lower="-1.745" upper="1.745" effort="0" velocity="2.62" />
    </joint>
    <joint name="${prefix}left_E_axis" type="revolute">
          <parent link="left_E_link" />
          <child link="left_U_link" />
          <origin xyz="0 0.23549999999989 0" rpy="0 0 0" />
          <axis xyz="0 1 0" />
        <limit lower="-2.966" upper="2.966" effort="0" velocity="2.97" />
    </joint>
    <joint name="${prefix}left_U_axis" type="revolute">
          <parent link="left_U_link" />
          <child link="left_R_link" />
          <origin xyz="0.065 0.1445 0" rpy="0 0 0" />
          <axis xyz="0 0 1" />
          <limit lower="-1.396" upper="0.7504" effort="0" velocity="2.97" />
    </joint>
    <joint name="${prefix}left_R_axis" type="revolute">
          <parent link="left_R_link" />
          <child link="left_B_link" />
          <origin xyz="0.35997 0.05 0" rpy="0 0 0" />
          <axis xyz="-1 0 0" />
          <limit lower="-3.1415" upper="3.1415" effort="0" velocity="3.49" />
    </joint>
    <joint name="${prefix}left_B_axis" type="revolute">
          <parent link="left_B_link" />
          <child link="left_T_link" />
          <origin xyz="0 0 0" rpy="0 0 0" />
          <axis xyz="0 0 1" />
          <limit lower="-1.9198" upper="1.9198" effort="0" velocity="3.49" />
    </joint>
 
    <joint name="${prefix}left_T_axis" type="revolute">
          <parent link="left_T_link" />
          <child link="left_tool_0" />
          <origin xyz="0.138 0 0" rpy="0 0 0" />
          <axis xyz="-1 0 0" />
          <limit lower="-4.712" upper="4.712" effort="0" velocity="6.11" />
    </joint>
		<!-- end of joint list -->
	</xacro:macro>
</robot>
