<?xml version="1.0" ?>
<!-- =================================================================================== -->
<!-- |    This document was autogenerated by xacro from motoman_bmda3.xacro            | -->
<!-- |    EDITING THIS FILE BY HAND IS NOT RECOMMENDED                                 | -->
<!-- =================================================================================== -->
<robot name="motoman_bmda3" xmlns:xacro="http://ros.org/wiki/xacro">
  <link name="world">
    <origin rpy="0 0 0" xyz="0 0 0"/>
  </link>
  <link name="base_link">
    <visual>
      <origin rpy="0 0 0" xyz="0 0 0"/>
      <geometry>
        <mesh filename="package://motoman_bmda3_support/meshes/bmda3/visual/base_link.stl"/>
      </geometry>
      <material name="">
        <color rgba="0.75294 0.75294 0.75294 1"/>
      </material>
    </visual>
    <collision>
      <origin rpy="0 0 0" xyz="0 0 0"/>
      <geometry>
        <mesh filename="package://motoman_bmda3_support/meshes/bmda3/collision/base_link.stl"/>
      </geometry>
    </collision>
  </link>
  <link name="waist_link">
    <visual>
      <origin rpy="0 0 0" xyz="0 0 0"/>
      <geometry>
        <mesh filename="package://motoman_bmda3_support/meshes/bmda3/visual/waist_link.stl"/>
      </geometry>
      <material name="">
        <color rgba="0.75294 0.75294 0.75294 1"/>
      </material>
    </visual>
    <collision>
      <origin rpy="0 0 0" xyz="0 0 0"/>
      <geometry>
        <mesh filename="package://motoman_bmda3_support/meshes/bmda3/collision/waist_link.stl"/>
      </geometry>
    </collision>
  </link>
  <link name="right_L_link">
    <visual>
      <origin rpy="0 0 0" xyz="0 0 0"/>
      <geometry>
        <mesh filename="package://motoman_bmda3_support/meshes/bmda3/visual/right_L_link.stl"/>
      </geometry>
      <material name="">
        <color rgba="0.75294 0.75294 0.75294 1"/>
      </material>
    </visual>
    <collision>
      <origin rpy="0 0 0" xyz="0 0 0"/>
      <geometry>
        <mesh filename="package://motoman_bmda3_support/meshes/bmda3/collision/right_L_link.stl"/>
      </geometry>
    </collision>
  </link>
  <link name="right_E_link">
    <visual>
      <origin rpy="0 0 0" xyz="0 0 0"/>
      <geometry>
        <mesh filename="package://motoman_bmda3_support/meshes/bmda3/visual/right_E_link.stl"/>
      </geometry>
      <material name="">
        <color rgba="0.75294 0.75294 0.75294 1"/>
      </material>
    </visual>
    <collision>
      <origin rpy="0 0 0" xyz="0 0 0"/>
      <geometry>
        <mesh filename="package://motoman_bmda3_support/meshes/bmda3/collision/right_E_link.stl"/>
      </geometry>
    </collision>
  </link>
  <link name="right_U_link">
    <visual>
      <origin rpy="0 0 0" xyz="0 0 0"/>
      <geometry>
        <mesh filename="package://motoman_bmda3_support/meshes/bmda3/visual/right_U_link.stl"/>
      </geometry>
      <material name="">
        <color rgba="0.752941176470588 0.752941176470588 0.752941176470588 1"/>
      </material>
    </visual>
    <collision>
      <origin rpy="0 0 0" xyz="0 0 0"/>
      <geometry>
        <mesh filename="package://motoman_bmda3_support/meshes/bmda3/collision/right_U_link.stl"/>
      </geometry>
    </collision>
  </link>
  <link name="right_R_link">
    <visual>
      <origin rpy="0 0 0" xyz="0 0 0"/>
      <geometry>
        <mesh filename="package://motoman_bmda3_support/meshes/bmda3/visual/right_R_link.stl"/>
      </geometry>
      <material name="">
        <color rgba="0.752941176470588 0.752941176470588 0.752941176470588 1"/>
      </material>
    </visual>
    <collision>
      <origin rpy="0 0 0" xyz="0 0 0"/>
      <geometry>
        <mesh filename="package://motoman_bmda3_support/meshes/bmda3/collision/right_R_link.stl"/>
      </geometry>
    </collision>
  </link>
  <link name="right_B_link">
    <visual>
      <origin rpy="0 0 0" xyz="0 0 0"/>
      <geometry>
        <mesh filename="package://motoman_bmda3_support/meshes/bmda3/visual/right_B_link.stl"/>
      </geometry>
      <material name="">
        <color rgba="0.752941176470588 0.752941176470588 0.752941176470588 1"/>
      </material>
    </visual>
    <collision>
      <origin rpy="0 0 0" xyz="0 0 0"/>
      <geometry>
        <mesh filename="package://motoman_bmda3_support/meshes/bmda3/collision/right_B_link.stl"/>
      </geometry>
    </collision>
  </link>
  <link name="right_T_link">
    <visual>
      <origin rpy="0 0 0" xyz="0 0 0"/>
      <geometry>
        <mesh filename="package://motoman_bmda3_support/meshes/bmda3/visual/right_T_link.stl"/>
      </geometry>
      <material name="">
        <color rgba="0.752941176470588 0.752941176470588 0.752941176470588 1"/>
      </material>
    </visual>
    <collision>
      <origin rpy="0 0 0" xyz="0 0 0"/>
      <geometry>
        <mesh filename="package://motoman_bmda3_support/meshes/bmda3/collision/right_T_link.stl"/>
      </geometry>
    </collision>
  </link>
  <link name="right_tool_0">
    <visual>
      <origin rpy="0 0 0" xyz="0 0 0"/>
      <geometry>
        <mesh filename="package://motoman_bmda3_support/meshes/bmda3/visual/right_tool_0.stl"/>
      </geometry>
      <material name="">
        <color rgba="0.752941176470588 0.752941176470588 0.752941176470588 1"/>
      </material>
    </visual>
    <collision>
      <origin rpy="0 0 0" xyz="0 0 0"/>
      <geometry>
        <mesh filename="package://motoman_bmda3_support/meshes/bmda3/collision/right_tool_0.stl"/>
      </geometry>
    </collision>
  </link>
  <link name="left_L_link">
    <visual>
      <origin rpy="0 0 0" xyz="0 0 0"/>
      <geometry>
        <mesh filename="package://motoman_bmda3_support/meshes/bmda3/visual/left_L_link.stl"/>
      </geometry>
      <material name="">
        <color rgba="0.752941176470588 0.752941176470588 0.752941176470588 1"/>
      </material>
    </visual>
    <collision>
      <origin rpy="0 0 0" xyz="0 0 0"/>
      <geometry>
        <mesh filename="package://motoman_bmda3_support/meshes/bmda3/collision/left_L_link.stl"/>
      </geometry>
    </collision>
  </link>
  <link name="left_E_link">
    <visual>
      <origin rpy="0 0 0" xyz="0 0 0"/>
      <geometry>
        <mesh filename="package://motoman_bmda3_support/meshes/bmda3/visual/left_E_link.stl"/>
      </geometry>
      <material name="">
        <color rgba="0.752941176470588 0.752941176470588 0.752941176470588 1"/>
      </material>
    </visual>
    <collision>
      <origin rpy="0 0 0" xyz="0 0 0"/>
      <geometry>
        <mesh filename="package://motoman_bmda3_support/meshes/bmda3/collision/left_E_link.stl"/>
      </geometry>
    </collision>
  </link>
  <link name="left_U_link">
    <visual>
      <origin rpy="0 0 0" xyz="0 0 0"/>
      <geometry>
        <mesh filename="package://motoman_bmda3_support/meshes/bmda3/visual/left_U_link.stl"/>
      </geometry>
      <material name="">
        <color rgba="0.752941176470588 0.752941176470588 0.752941176470588 1"/>
      </material>
    </visual>
    <collision>
      <origin rpy="0 0 0" xyz="0 0 0"/>
      <geometry>
        <mesh filename="package://motoman_bmda3_support/meshes/bmda3/collision/left_U_link.stl"/>
      </geometry>
    </collision>
  </link>
  <link name="left_R_link">
    <visual>
      <origin rpy="0 0 0" xyz="0 0 0"/>
      <geometry>
        <mesh filename="package://motoman_bmda3_support/meshes/bmda3/visual/left_R_link.stl"/>
      </geometry>
      <material name="">
        <color rgba="0.752941176470588 0.752941176470588 0.752941176470588 1"/>
      </material>
    </visual>
    <collision>
      <origin rpy="0 0 0" xyz="0 0 0"/>
      <geometry>
        <mesh filename="package://motoman_bmda3_support/meshes/bmda3/collision/left_R_link.stl"/>
      </geometry>
    </collision>
  </link>
  <link name="left_B_link">
    <visual>
      <origin rpy="0 0 0" xyz="0 0 0"/>
      <geometry>
        <mesh filename="package://motoman_bmda3_support/meshes/bmda3/visual/left_B_link.stl"/>
      </geometry>
      <material name="">
        <color rgba="0.752941176470588 0.752941176470588 0.752941176470588 1"/>
      </material>
    </visual>
    <collision>
      <origin rpy="0 0 0" xyz="0 0 0"/>
      <geometry>
        <mesh filename="package://motoman_bmda3_support/meshes/bmda3/collision/left_B_link.stl"/>
      </geometry>
    </collision>
  </link>
  <link name="left_T_link">
    <visual>
      <origin rpy="0 0 0" xyz="0 0 0"/>
      <geometry>
        <mesh filename="package://motoman_bmda3_support/meshes/bmda3/visual/left_T_link.stl"/>
      </geometry>
      <material name="">
        <color rgba="0.752941176470588 0.752941176470588 0.752941176470588 1"/>
      </material>
    </visual>
    <collision>
      <origin rpy="0 0 0" xyz="0 0 0"/>
      <geometry>
        <mesh filename="package://motoman_bmda3_support/meshes/bmda3/collision/left_T_link.stl"/>
      </geometry>
    </collision>
  </link>
  <link name="left_tool_0">
    <visual>
      <origin rpy="0 0 0" xyz="0 0 0"/>
      <geometry>
        <mesh filename="package://motoman_bmda3_support/meshes/bmda3/visual/left_tool_0.stl"/>
      </geometry>
      <material name="">
        <color rgba="0.752941176470588 0.752941176470588 0.752941176470588 1"/>
      </material>
    </visual>
    <collision>
      <origin rpy="0 0 0" xyz="0 0 0"/>
      <geometry>
        <mesh filename="package://motoman_bmda3_support/meshes/bmda3/collision/left_tool_0.stl"/>
      </geometry>
    </collision>
  </link>
  <joint name="world-base" type="fixed">
    <origin rpy="0 0 0" xyz="0 0 0"/>
    <parent link="world"/>
    <child link="base_link"/>
  </joint>
  <joint name="waist_axis" type="revolute">
    <parent link="base_link"/>
    <child link="waist_link"/>
    <origin rpy="0 0 0" xyz="0 0 0.3305"/>
    <axis xyz="0 0 1"/>
    <limit effort="0" lower="-3.14" upper="3.14" velocity="2.27"/>
  </joint>
  <joint name="right_S_axis" type="revolute">
    <parent link="waist_link"/>
    <child link="right_L_link"/>
    <origin rpy="0 0 0" xyz="0.15002 -0.099 0.12951"/>
    <axis xyz="0 1 0"/>
    <limit effort="0" lower="-1.57" upper="3.14" velocity="2.97"/>
  </joint>
  <joint name="right_L_axis" type="revolute">
    <parent link="right_L_link"/>
    <child link="right_E_link"/>
    <origin rpy="0 0 0" xyz="0 -0.151 0"/>
    <axis xyz="0 0 1"/>
    <limit effort="0" lower="-1.745" upper="1.745" velocity="2.62"/>
  </joint>
  <joint name="right_E_axis" type="revolute">
    <parent link="right_E_link"/>
    <child link="right_U_link"/>
    <origin rpy="0 0 0" xyz="0 -0.23549999999989 0"/>
    <axis xyz="0 1 0"/>
    <limit effort="0" lower="-2.966" upper="2.966" velocity="2.97"/>
  </joint>
  <joint name="right_U_axis" type="revolute">
    <parent link="right_U_link"/>
    <child link="right_R_link"/>
    <origin rpy="0 0 0" xyz="0.065002 -0.1445 0"/>
    <axis xyz="0 0 -1"/>
    <limit effort="0" lower="-1.396" upper="0.7504" velocity="2.97"/>
  </joint>
  <joint name="right_R_axis" type="revolute">
    <parent link="right_R_link"/>
    <child link="right_B_link"/>
    <origin rpy="0 0 0" xyz="0.35997 -0.05 0"/>
    <axis xyz="1 0 0"/>
    <limit effort="0" lower="-3.1415" upper="3.1415" velocity="3.49"/>
  </joint>
  <joint name="right_B_axis" type="revolute">
    <parent link="right_B_link"/>
    <child link="right_T_link"/>
    <origin rpy="0 0 0" xyz="0 0 0"/>
    <axis xyz="0 0 -1"/>
    <limit effort="0" lower="-1.9198" upper="1.9198" velocity="3.49"/>
  </joint>
  <joint name="right_T_axis" type="revolute">
    <parent link="right_T_link"/>
    <child link="right_tool_0"/>
    <origin rpy="0 0 0" xyz="0.138 0 0"/>
    <axis xyz="1 0 0"/>
    <limit effort="0" lower="-4.712" upper="4.712" velocity="6.11"/>
  </joint>
  <joint name="left_S_axis" type="revolute">
    <parent link="waist_link"/>
    <child link="left_L_link"/>
    <origin rpy="0 0 0" xyz="0.15003 0.099 0.1295"/>
    <axis xyz="0 1 0"/>
    <limit effort="0" lower="-1.57" upper="3.1415" velocity="2.97"/>
  </joint>
  <joint name="left_L_axis" type="revolute">
    <parent link="left_L_link"/>
    <child link="left_E_link"/>
    <origin rpy="0 0 0" xyz="0 0.151 0"/>
    <axis xyz="0 0 -1"/>
    <limit effort="0" lower="-1.745" upper="1.745" velocity="2.62"/>
  </joint>
  <joint name="left_E_axis" type="revolute">
    <parent link="left_E_link"/>
    <child link="left_U_link"/>
    <origin rpy="0 0 0" xyz="0 0.23549999999989 0"/>
    <axis xyz="0 1 0"/>
    <limit effort="0" lower="-2.966" upper="2.966" velocity="2.97"/>
  </joint>
  <joint name="left_U_axis" type="revolute">
    <parent link="left_U_link"/>
    <child link="left_R_link"/>
    <origin rpy="0 0 0" xyz="0.065 0.1445 0"/>
    <axis xyz="0 0 1"/>
    <limit effort="0" lower="-1.396" upper="0.7504" velocity="2.97"/>
  </joint>
  <joint name="left_R_axis" type="revolute">
    <parent link="left_R_link"/>
    <child link="left_B_link"/>
    <origin rpy="0 0 0" xyz="0.35997 0.05 0"/>
    <axis xyz="-1 0 0"/>
    <limit effort="0" lower="-3.1415" upper="3.1415" velocity="3.49"/>
  </joint>
  <joint name="left_B_axis" type="revolute">
    <parent link="left_B_link"/>
    <child link="left_T_link"/>
    <origin rpy="0 0 0" xyz="0 0 0"/>
    <axis xyz="0 0 1"/>
    <limit effort="0" lower="-1.9198" upper="1.9198" velocity="3.49"/>
  </joint>
  <joint name="left_T_axis" type="revolute">
    <parent link="left_T_link"/>
    <child link="left_tool_0"/>
    <origin rpy="0 0 0" xyz="0.138 0 0"/>
    <axis xyz="-1 0 0"/>
    <limit effort="0" lower="-4.712" upper="4.712" velocity="6.11"/>
  </joint>
</robot>
