<?xml version="1.0" ?>
<!-- =================================================================================== -->
<!-- |    This document was autogenerated by xacro from motoman_bmda3.xacro            | -->
<!-- |    EDITING THIS FILE BY HAND IS NOT RECOMMENDED                                 | -->
<!-- =================================================================================== -->
<robot name="motoman_bmda3" xmlns:xacro="http://ros.org/wiki/xacro">
  <link name="base_link">
    <origin rpy="0 0 0" xyz="0 0 0"/>
  </link>
  <link name="base">
    <visual>
      <origin rpy="0 0 0" xyz="0 0 0"/>
      <geometry>
        <mesh filename="package://motoman_bmda3_support/meshes/bmda3/visual/base.stl"/>
      </geometry>
      <material name="">
        <color rgba="0.75294 0.75294 0.75294 1"/>
      </material>
    </visual>
    <collision>
      <origin rpy="0 0 0" xyz="0 0 0"/>
      <geometry>
        <mesh filename="package://motoman_bmda3_support/meshes/bmda3/collision/base.stl"/>
      </geometry>
    </collision>
  </link>
  <link name="waist_link">
    <visual>
      <origin rpy="0 0 0" xyz="0 0 0"/>
      <geometry>
        <mesh filename="package://motoman_bmda3_support/meshes/bmda3/visual/waist_link.stl"/>
      </geometry>
      <material name="">
        <color rgba="0.75294 0.75294 0.75294 1"/>
      </material>
    </visual>
    <collision>
      <origin rpy="0 0 0" xyz="0 0 0"/>
      <geometry>
        <mesh filename="package://motoman_bmda3_support/meshes/bmda3/collision/waist_link.stl"/>
      </geometry>
    </collision>
  </link>
  <link name="right_link_L">
    <visual>
      <origin rpy="0 0 0" xyz="0 0 0"/>
      <geometry>
        <mesh filename="package://motoman_bmda3_support/meshes/bmda3/visual/right_link_L.stl"/>
      </geometry>
      <material name="">
        <color rgba="0.75294 0.75294 0.75294 1"/>
      </material>
    </visual>
    <collision>
      <origin rpy="0 0 0" xyz="0 0 0"/>
      <geometry>
        <mesh filename="package://motoman_bmda3_support/meshes/bmda3/collision/right_link_L.stl"/>
      </geometry>
    </collision>
  </link>
  <link name="right_link_E">
    <visual>
      <origin rpy="0 0 0" xyz="0 0 0"/>
      <geometry>
        <mesh filename="package://motoman_bmda3_support/meshes/bmda3/visual/right_link_E.stl"/>
      </geometry>
      <material name="">
        <color rgba="0.75294 0.75294 0.75294 1"/>
      </material>
    </visual>
    <collision>
      <origin rpy="0 0 0" xyz="0 0 0"/>
      <geometry>
        <mesh filename="package://motoman_bmda3_support/meshes/bmda3/collision/right_link_E.stl"/>
      </geometry>
    </collision>
  </link>
  <link name="right_link_U">
    <visual>
      <origin rpy="0 0 0" xyz="0 0 0"/>
      <geometry>
        <mesh filename="package://motoman_bmda3_support/meshes/bmda3/visual/right_link_U.stl"/>
      </geometry>
      <material name="">
        <color rgba="0.752941176470588 0.752941176470588 0.752941176470588 1"/>
      </material>
    </visual>
    <collision>
      <origin rpy="0 0 0" xyz="0 0 0"/>
      <geometry>
        <mesh filename="package://motoman_bmda3_support/meshes/bmda3/collision/right_link_U.stl"/>
      </geometry>
    </collision>
  </link>
  <link name="right_link_R">
    <visual>
      <origin rpy="0 0 0" xyz="0 0 0"/>
      <geometry>
        <mesh filename="package://motoman_bmda3_support/meshes/bmda3/visual/right_link_R.stl"/>
      </geometry>
      <material name="">
        <color rgba="0.752941176470588 0.752941176470588 0.752941176470588 1"/>
      </material>
    </visual>
    <collision>
      <origin rpy="0 0 0" xyz="0 0 0"/>
      <geometry>
        <mesh filename="package://motoman_bmda3_support/meshes/bmda3/collision/right_link_R.stl"/>
      </geometry>
    </collision>
  </link>
  <link name="right_link_B">
    <visual>
      <origin rpy="0 0 0" xyz="0 0 0"/>
      <geometry>
        <mesh filename="package://motoman_bmda3_support/meshes/bmda3/visual/right_link_B.stl"/>
      </geometry>
      <material name="">
        <color rgba="0.752941176470588 0.752941176470588 0.752941176470588 1"/>
      </material>
    </visual>
    <collision>
      <origin rpy="0 0 0" xyz="0 0 0"/>
      <geometry>
        <mesh filename="package://motoman_bmda3_support/meshes/bmda3/collision/right_link_B.stl"/>
      </geometry>
    </collision>
  </link>
  <link name="right_link_T">
    <visual>
      <origin rpy="0 0 0" xyz="0 0 0"/>
      <geometry>
        <mesh filename="package://motoman_bmda3_support/meshes/bmda3/visual/right_link_T.stl"/>
      </geometry>
      <material name="">
        <color rgba="0.752941176470588 0.752941176470588 0.752941176470588 1"/>
      </material>
    </visual>
    <collision>
      <origin rpy="0 0 0" xyz="0 0 0"/>
      <geometry>
        <mesh filename="package://motoman_bmda3_support/meshes/bmda3/collision/right_link_T.stl"/>
      </geometry>
    </collision>
  </link>
  <link name="right_tool_0">
    <visual>
      <origin rpy="0 0 0" xyz="0 0 0"/>
      <geometry>
        <mesh filename="package://motoman_bmda3_support/meshes/bmda3/visual/right_tool_0.stl"/>
      </geometry>
      <material name="">
        <color rgba="0.752941176470588 0.752941176470588 0.752941176470588 1"/>
      </material>
    </visual>
    <collision>
      <origin rpy="0 0 0" xyz="0 0 0"/>
      <geometry>
        <mesh filename="package://motoman_bmda3_support/meshes/bmda3/collision/right_tool_0.stl"/>
      </geometry>
    </collision>
  </link>
  <link name="left_link_L">
    <visual>
      <origin rpy="0 0 0" xyz="0 0 0"/>
      <geometry>
        <mesh filename="package://motoman_bmda3_support/meshes/bmda3/visual/left_link_L.stl"/>
      </geometry>
      <material name="">
        <color rgba="0.752941176470588 0.752941176470588 0.752941176470588 1"/>
      </material>
    </visual>
    <collision>
      <origin rpy="0 0 0" xyz="0 0 0"/>
      <geometry>
        <mesh filename="package://motoman_bmda3_support/meshes/bmda3/collision/left_link_L.stl"/>
      </geometry>
    </collision>
  </link>
  <link name="left_link_E">
    <visual>
      <origin rpy="0 0 0" xyz="0 0 0"/>
      <geometry>
        <mesh filename="package://motoman_bmda3_support/meshes/bmda3/visual/left_link_E.stl"/>
      </geometry>
      <material name="">
        <color rgba="0.752941176470588 0.752941176470588 0.752941176470588 1"/>
      </material>
    </visual>
    <collision>
      <origin rpy="0 0 0" xyz="0 0 0"/>
      <geometry>
        <mesh filename="package://motoman_bmda3_support/meshes/bmda3/collision/left_link_E.stl"/>
      </geometry>
    </collision>
  </link>
  <link name="left_link_U">
    <visual>
      <origin rpy="0 0 0" xyz="0 0 0"/>
      <geometry>
        <mesh filename="package://motoman_bmda3_support/meshes/bmda3/visual/left_link_U.stl"/>
      </geometry>
      <material name="">
        <color rgba="0.752941176470588 0.752941176470588 0.752941176470588 1"/>
      </material>
    </visual>
    <collision>
      <origin rpy="0 0 0" xyz="0 0 0"/>
      <geometry>
        <mesh filename="package://motoman_bmda3_support/meshes/bmda3/collision/left_link_U.stl"/>
      </geometry>
    </collision>
  </link>
  <link name="left_link_R">
    <visual>
      <origin rpy="0 0 0" xyz="0 0 0"/>
      <geometry>
        <mesh filename="package://motoman_bmda3_support/meshes/bmda3/visual/left_link_R.stl"/>
      </geometry>
      <material name="">
        <color rgba="0.752941176470588 0.752941176470588 0.752941176470588 1"/>
      </material>
    </visual>
    <collision>
      <origin rpy="0 0 0" xyz="0 0 0"/>
      <geometry>
        <mesh filename="package://motoman_bmda3_support/meshes/bmda3/collision/left_link_R.stl"/>
      </geometry>
    </collision>
  </link>
  <link name="left_link_B">
    <visual>
      <origin rpy="0 0 0" xyz="0 0 0"/>
      <geometry>
        <mesh filename="package://motoman_bmda3_support/meshes/bmda3/visual/left_link_B.stl"/>
      </geometry>
      <material name="">
        <color rgba="0.752941176470588 0.752941176470588 0.752941176470588 1"/>
      </material>
    </visual>
    <collision>
      <origin rpy="0 0 0" xyz="0 0 0"/>
      <geometry>
        <mesh filename="package://motoman_bmda3_support/meshes/bmda3/collision/left_link_B.stl"/>
      </geometry>
    </collision>
  </link>
  <link name="left_link_T">
    <visual>
      <origin rpy="0 0 0" xyz="0 0 0"/>
      <geometry>
        <mesh filename="package://motoman_bmda3_support/meshes/bmda3/visual/left_link_T.stl"/>
      </geometry>
      <material name="">
        <color rgba="0.752941176470588 0.752941176470588 0.752941176470588 1"/>
      </material>
    </visual>
    <collision>
      <origin rpy="0 0 0" xyz="0 0 0"/>
      <geometry>
        <mesh filename="package://motoman_bmda3_support/meshes/bmda3/collision/left_link_T.stl"/>
      </geometry>
    </collision>
  </link>
  <link name="left_tool_0">
    <visual>
      <origin rpy="0 0 0" xyz="0 0 0"/>
      <geometry>
        <mesh filename="package://motoman_bmda3_support/meshes/bmda3/visual/left_tool_0.stl"/>
      </geometry>
      <material name="">
        <color rgba="0.752941176470588 0.752941176470588 0.752941176470588 1"/>
      </material>
    </visual>
    <collision>
      <origin rpy="0 0 0" xyz="0 0 0"/>
      <geometry>
        <mesh filename="package://motoman_bmda3_support/meshes/bmda3/collision/left_tool_0.stl"/>
      </geometry>
    </collision>
  </link>
  <joint name="base_link-base" type="fixed">
    <origin rpy="0 0 0" xyz="0 0 0"/>
    <parent link="base_link"/>
    <child link="base"/>
  </joint>
  <joint name="waist" type="revolute">
    <parent link="base"/>
    <child link="waist_link"/>
    <origin rpy="0 0 0" xyz="0 0 0.3305"/>
    <axis xyz="0 0 1"/>
    <limit effort="0" lower="-3.14" upper="3.14" velocity="2.27"/>
  </joint>
  <joint name="right_joint_S" type="revolute">
    <parent link="waist_link"/>
    <child link="right_link_L"/>
    <origin rpy="0 0 0" xyz="0.15002 -0.099 0.12951"/>
    <axis xyz="0 1 0"/>
    <limit effort="0" lower="-1.57" upper="3.14" velocity="2.97"/>
  </joint>
  <joint name="right_joint_L" type="revolute">
    <parent link="right_link_L"/>
    <child link="right_link_E"/>
    <origin rpy="0 0 0" xyz="0 -0.151 0"/>
    <axis xyz="0 0 1"/>
    <limit effort="0" lower="-1.745" upper="1.745" velocity="2.62"/>
  </joint>
  <joint name="right_joint_E" type="revolute">
    <parent link="right_link_E"/>
    <child link="right_link_U"/>
    <origin rpy="0 0 0" xyz="0 -0.23549999999989 0"/>
    <axis xyz="0 1 0"/>
    <limit effort="0" lower="-2.966" upper="2.966" velocity="2.97"/>
  </joint>
  <joint name="right_joint_U" type="revolute">
    <parent link="right_link_U"/>
    <child link="right_link_R"/>
    <origin rpy="0 0 0" xyz="0.065002 -0.1445 0"/>
    <axis xyz="0 0 -1"/>
    <limit effort="0" lower="-1.396" upper="0.7504" velocity="2.97"/>
  </joint>
  <joint name="right_joint_R" type="revolute">
    <parent link="right_link_R"/>
    <child link="right_link_B"/>
    <origin rpy="0 0 0" xyz="0.35997 -0.05 0"/>
    <axis xyz="1 0 0"/>
    <limit effort="0" lower="-3.1415" upper="3.1415" velocity="3.49"/>
  </joint>
  <joint name="right_joint_B" type="revolute">
    <parent link="right_link_B"/>
    <child link="right_link_T"/>
    <origin rpy="0 0 0" xyz="0 0 0"/>
    <axis xyz="0 0 -1"/>
    <limit effort="0" lower="-1.9198" upper="1.9198" velocity="3.49"/>
  </joint>
  <joint name="right_joint_T" type="revolute">
    <parent link="right_link_T"/>
    <child link="right_tool_0"/>
    <origin rpy="0 0 0" xyz="0.138 0 0"/>
    <axis xyz="1 0 0"/>
    <limit effort="0" lower="-4.712" upper="4.712" velocity="6.11"/>
  </joint>
  <joint name="left_joint_S" type="revolute">
    <parent link="waist_link"/>
    <child link="left_link_L"/>
    <origin rpy="0 0 0" xyz="0.15003 0.099 0.1295"/>
    <axis xyz="0 1 0"/>
    <limit effort="0" lower="-1.57" upper="3.1415" velocity="2.97"/>
  </joint>
  <joint name="left_joint_L" type="revolute">
    <parent link="left_link_L"/>
    <child link="left_link_E"/>
    <origin rpy="0 0 0" xyz="0 0.151 0"/>
    <axis xyz="0 0 -1"/>
    <limit effort="0" lower="-1.745" upper="1.745" velocity="2.62"/>
  </joint>
  <joint name="left_joint_E" type="revolute">
    <parent link="left_link_E"/>
    <child link="left_link_U"/>
    <origin rpy="0 0 0" xyz="0 0.23549999999989 0"/>
    <axis xyz="0 1 0"/>
    <limit effort="0" lower="-2.966" upper="2.966" velocity="2.97"/>
  </joint>
  <joint name="left_joint_U" type="revolute">
    <parent link="left_link_U"/>
    <child link="left_link_R"/>
    <origin rpy="0 0 0" xyz="0.065 0.1445 0"/>
    <axis xyz="0 0 1"/>
    <limit effort="0" lower="-1.396" upper="0.7504" velocity="2.97"/>
  </joint>
  <joint name="left_joint_R" type="revolute">
    <parent link="left_link_R"/>
    <child link="left_link_B"/>
    <origin rpy="0 0 0" xyz="0.35997 0.05 0"/>
    <axis xyz="-1 0 0"/>
    <limit effort="0" lower="-3.1415" upper="3.1415" velocity="3.49"/>
  </joint>
  <joint name="left_joint_B" type="revolute">
    <parent link="left_link_B"/>
    <child link="left_link_T"/>
    <origin rpy="0 0 0" xyz="0 0 0"/>
    <axis xyz="0 0 1"/>
    <limit effort="0" lower="-1.9198" upper="1.9198" velocity="3.49"/>
  </joint>
  <joint name="left_joint_T" type="revolute">
    <parent link="left_link_T"/>
    <child link="left_tool_0"/>
    <origin rpy="0 0 0" xyz="0.138 0 0"/>
    <axis xyz="-1 0 0"/>
    <limit effort="0" lower="-4.712" upper="4.712" velocity="6.11"/>
  </joint>
</robot>
