<?xml version="1.0" ?>
<robot xmlns:xacro="http://ros.org/wiki/xacro">
  <xacro:macro name="motoman_mpx3500" params="prefix">

    <!-- Properties -->
    <material name="yaskawa_blue">
          <color rgba="0.12941 0.14902 0.74902 1" />
    </material>
    <material name="yaskawa_white">
          <color rgba="0.95 0.95 0.95 1" />
    </material>
    <material name="yaskawa_silver">
          <color rgba="0.75294 0.75294 0.75294 1" />
    </material>

    <!-- link list -->
    <link name="${prefix}base_link">
        <visual>
            <geometry>
                <mesh filename="package://motoman_mpx3500_support/meshes/mpx3500/visual/base_link.stl"/>
            </geometry>
            <material name="yaskawa_blue"/>
        </visual>
        <collision>
            <geometry>
                <mesh filename="package://motoman_mpx3500_support/meshes/mpx3500/collision/base_link.stl"/>
            </geometry>
        </collision>
    </link>
    <link name="${prefix}link_1_s">
        <visual>
            <geometry>
                <mesh filename="package://motoman_mpx3500_support/meshes/mpx3500/visual/link_1_s.stl"/>
            </geometry>
            <material name="yaskawa_blue"/>
        </visual>
        <collision>
            <geometry>
                <mesh filename="package://motoman_mpx3500_support/meshes/mpx3500/collision/link_1_s.stl"/>
            </geometry>
        </collision>
    </link>
    <link name="${prefix}link_2_l">
        <visual>
            <geometry>
                <mesh filename="package://motoman_mpx3500_support/meshes/mpx3500/visual/link_2_l.stl"/>
            </geometry>
            <material name="yaskawa_blue"/>
        </visual>
        <collision>
            <geometry>
                <mesh filename="package://motoman_mpx3500_support/meshes/mpx3500/collision/link_2_l.stl"/>
            </geometry>
        </collision>
    </link>
    <link name="${prefix}link_3_u">
        <visual>
            <geometry>
                <mesh filename="package://motoman_mpx3500_support/meshes/mpx3500/visual/link_3_u.stl"/>
            </geometry>
            <material name="yaskawa_blue"/>
        </visual>
        <collision>
            <geometry>
                <mesh filename="package://motoman_mpx3500_support/meshes/mpx3500/collision/link_3_u.stl"/>
            </geometry>
        </collision>
    </link>
    <link name="${prefix}link_4_r">
        <visual>
            <geometry>
                <mesh filename="package://motoman_mpx3500_support/meshes/mpx3500/visual/link_4_r.stl"/>
            </geometry>
            <material name="yaskawa_white"/>
        </visual>
        <collision>
            <geometry>
                <mesh filename="package://motoman_mpx3500_support/meshes/mpx3500/collision/link_4_r.stl"/>
            </geometry>
        </collision>
    </link>
    <link name="${prefix}link_5_b">
        <visual>
            <geometry>
                <mesh filename="package://motoman_mpx3500_support/meshes/mpx3500/visual/link_5_b.stl"/>
            </geometry>
            <material name="yaskawa_white"/>
        </visual>
        <collision>
            <geometry>
                <mesh filename="package://motoman_mpx3500_support/meshes/mpx3500/collision/link_5_b.stl"/>
            </geometry>
        </collision>
    </link>
    <link name="${prefix}link_6_t">
        <visual>
            <geometry>
                <mesh filename="package://motoman_mpx3500_support/meshes/mpx3500/visual/link_6_t.stl"/>
            </geometry>
            <material name="yaskawa_silver"/>
        </visual>
        <collision>
            <geometry>
                <mesh filename="package://motoman_mpx3500_support/meshes/mpx3500/collision/link_6_t.stl"/>
            </geometry>
        </collision>
    </link>
    <link name="${prefix}tool0"/>
    <!-- end of link list -->

    <!-- joint list -->
    <joint name="${prefix}joint_1_s" type="revolute">
        <parent link="${prefix}base_link"/>
        <child link="${prefix}link_1_s"/>
        <origin xyz="0 0 0.800" rpy="0 0 0" />
        <axis xyz="0 0 1" />
        <limit lower="${radians(-150)}" upper="${radians(150)}" effort="5516" velocity="${radians(100)}"/>
    </joint>
    <joint name="${prefix}joint_2_l" type="revolute">
        <parent link="${prefix}link_1_s"/>
        <child link="${prefix}link_2_l"/>
        <origin xyz="0 0 0" rpy="0 0 0" />
        <axis xyz="0 1 0" />
        <limit lower="${radians(-65)}" upper="${radians(140)}" effort="7060" velocity="${radians(100)}"/>
    </joint>
    <joint name="${prefix}joint_3_u" type="revolute">
        <parent link="${prefix}link_2_l"/>
        <child link="${prefix}link_3_u"/>
        <origin xyz="0 0 1.3" rpy="0 0 0" />
        <axis xyz="0 -1 0" />
        <limit lower="${radians(-65)}" upper="${radians(90)}" effort="3089" velocity="${radians(110)}"/>
    </joint>
    <joint name="${prefix}joint_4_r" type="revolute">
        <parent link="${prefix}link_3_u"/>
        <child link="${prefix}link_4_r"/>
        <origin xyz="1.4 0 0" rpy="0 0 0" />
        <axis xyz="-1 0 0" />
        <limit lower="${radians(-720)}" upper="${radians(720)}" effort="926" velocity="${radians(300)}"/>
    </joint>
    <joint name="${prefix}joint_5_b" type="revolute">
        <parent link="${prefix}link_4_r"/>
        <child link="${prefix}link_5_b"/>
        <origin xyz="0 0 0" rpy="0 ${radians(60)} 0" />
        <axis xyz="-1 0 0" />
        <limit lower="${radians(-720)}" upper="${radians(720)}" effort="794" velocity="${radians(360)}"/>
    </joint>
    <joint name="${prefix}joint_6_t" type="revolute">
        <parent link="${prefix}link_5_b"/>
        <child link="${prefix}link_6_t"/>
        <origin xyz="0.114 0 0" rpy="0 ${radians(-60)} 0" />
        <axis xyz="-1 0 0" />
        <limit lower="${radians(-720)}" upper="${radians(720)}" effort="375" velocity="${radians(360)}"/>
    </joint>
    <joint name="${prefix}joint_6_t-tool0" type="fixed">
        <origin xyz="0.123 0 0" rpy="3.1415926 -1.570796 0"/>
        <parent link="${prefix}link_6_t"/>
        <child link="${prefix}tool0"/>
    </joint>
    <!-- end of joint list -->

    <!-- ROS base_link to Robot Manufacturer World Coordinates transform -->
    <link name="${prefix}base" />
    <joint name="${prefix}base_link-base" type="fixed">
        <origin xyz="0 0 0.8" rpy="0 0 0"/>
        <parent link="${prefix}base_link"/>
        <child link="${prefix}base"/>
    </joint>

  </xacro:macro>
</robot>
